<mujoco model="tendril_seg_viewer">
  <compiler meshdir="out" angle="radian" autolimits="true"/>
  <option gravity="0 0 0"/>
  <visual><global offwidth="960" offheight="720"/>
    <headlight ambient="0.45 0.45 0.45" diffuse="0.55 0.55 0.55" specular="0.1 0.1 0.1"/>
  </visual>
  <asset>
    <mesh name="mount" file="mount.stl" scale="0.001 0.001 0.001"/>
    <mesh name="servo" file="servo.stl" scale="0.001 0.001 0.001"/>
    <mesh name="horn"  file="horn.stl"  scale="0.001 0.001 0.001"/>
    <material name="pla"   rgba="0.32 0.35 0.40 1"/>
    <material name="servo" rgba="0.10 0.10 0.12 1"/>
    <material name="horn"  rgba="0.85 0.85 0.88 1"/>
    <material name="tpu"   rgba="0.90 0.45 0.15 1"/>
  </asset>

  <worldbody>
    <light pos="0.08 0.18 0.22" dir="-0.2 -0.4 -1"/>
    <camera name="iso" pos="0.16 0.16 0.12" xyaxes="-0.728 0.686 0 -0.130 -0.138 0.981"/>

    <geom type="mesh" mesh="mount" material="pla"   contype="0" conaffinity="0"/>
    <geom type="mesh" mesh="servo" material="servo" contype="0" conaffinity="0"/>

    <!-- static bolt flange of the finger (rigid, bolted to the shelf) -->
    <geom type="box" size="0.00900 0.01000 0.00200"
          pos="0 0.00700 0.03900" material="tpu" contype="0" conaffinity="0"/>

    <!-- deck string guides (align to the channels) -->
    <site name="guide_p" pos="0.00250 0.00700 0.03700" size="0.0008"/>
    <site name="guide_n" pos="-0.00250 0.00700 0.03700" size="0.0008"/>

    <!-- servo horn: spins about Y in the bending plane -->
    <body name="horn_body" pos="0 0.00700 0.01500">
      <joint name="joint_horn" type="hinge" axis="0 1 0"/>
      <geom type="mesh" mesh="horn" material="horn" contype="0" conaffinity="0"/>
      <site name="hole_p" pos="0.00800 0 0" size="0.0009"/>
      <site name="hole_n" pos="-0.00800 0 0" size="0.0009"/>
    </body>

    <!-- flexible finger: vertebra hinge-chain -->
    <body name="v0" pos="0 0.00700 0.04450"><geom type="box" size="0.00400 0.00600 0.00350" material="tpu"/><site name="entry_p" pos="0.00250 0 -0.00350" size="0.0008"/><site name="entry_n" pos="-0.00250 0 -0.00350" size="0.0008"/><body name="v1" pos="0 0 0.01000"><joint name="j0" type="hinge" axis="0 1 0" pos="0 0 -0.00150"/><geom type="box" size="0.00400 0.00600 0.00350" material="tpu"/><body name="v2" pos="0 0 0.01000"><joint name="j1" type="hinge" axis="0 1 0" pos="0 0 -0.00150"/><geom type="box" size="0.00400 0.00600 0.00350" material="tpu"/><body name="v3" pos="0 0 0.01000"><joint name="j2" type="hinge" axis="0 1 0" pos="0 0 -0.00150"/><geom type="box" size="0.00400 0.00600 0.00350" material="tpu"/><body name="v4" pos="0 0 0.01000"><joint name="j3" type="hinge" axis="0 1 0" pos="0 0 -0.00150"/><geom type="box" size="0.00400 0.00600 0.00350" material="tpu"/><body name="v5" pos="0 0 0.01000"><joint name="j4" type="hinge" axis="0 1 0" pos="0 0 -0.00150"/><geom type="box" size="0.00400 0.00600 0.00350" material="tpu"/><body name="v6" pos="0 0 0.01000"><joint name="j5" type="hinge" axis="0 1 0" pos="0 0 -0.00150"/><geom type="box" size="0.00400 0.00600 0.00350" material="tpu"/><body name="v7" pos="0 0 0.01000"><joint name="j6" type="hinge" axis="0 1 0" pos="0 0 -0.00150"/><geom type="box" size="0.00400 0.00600 0.00350" material="tpu"/><body name="v8" pos="0 0 0.01000"><joint name="j7" type="hinge" axis="0 1 0" pos="0 0 -0.00150"/><geom type="box" size="0.00400 0.00600 0.00350" material="tpu"/></body></body></body></body></body></body></body></body></body>
  </worldbody>

  <tendon>
    <spatial name="t_p" width="0.0007" rgba="0.95 0.95 0.95 1">
      <site site="hole_p"/><site site="guide_p"/><site site="entry_p"/></spatial>
    <spatial name="t_n" width="0.0007" rgba="0.55 0.85 0.95 1">
      <site site="hole_n"/><site site="guide_n"/><site site="entry_n"/></spatial>
  </tendon>
</mujoco>